2024-12-03 13:14:58,787 - uvicorn.error - ERROR - Exception in ASGI application
Traceback (most recent call last):
  File "C:\Users\User\OneDrive\Desktop\Digital Land\Digital-Land-Server\venv\Lib\site-packages\uvicorn\protocols\http\httptools_impl.py", line 401, in run_asgi
    result = await app(  # type: ignore[func-returns-value]
             ^^^^^^^^^^^^^^^^^^^^^^^^^^^^^^^^^^^^^^^^^^^^^^
  File "C:\Users\User\OneDrive\Desktop\Digital Land\Digital-Land-Server\venv\Lib\site-packages\uvicorn\middleware\proxy_headers.py", line 60, in __call__
    return await self.app(scope, receive, send)
           ^^^^^^^^^^^^^^^^^^^^^^^^^^^^^^^^^^^^
  File "C:\Users\User\OneDrive\Desktop\Digital Land\Digital-Land-Server\venv\Lib\site-packages\fastapi\applications.py", line 1054, in __call__
    await super().__call__(scope, receive, send)
  File "C:\Users\User\OneDrive\Desktop\Digital Land\Digital-Land-Server\venv\Lib\site-packages\starlette\applications.py", line 113, in __call__
    await self.middleware_stack(scope, receive, send)
  File "C:\Users\User\OneDrive\Desktop\Digital Land\Digital-Land-Server\venv\Lib\site-packages\starlette\middleware\errors.py", line 187, in __call__
    raise exc
  File "C:\Users\User\OneDrive\Desktop\Digital Land\Digital-Land-Server\venv\Lib\site-packages\starlette\middleware\errors.py", line 165, in __call__
    await self.app(scope, receive, _send)
  File "C:\Users\User\OneDrive\Desktop\Digital Land\Digital-Land-Server\venv\Lib\site-packages\starlette\middleware\cors.py", line 93, in __call__
    await self.simple_response(scope, receive, send, request_headers=headers)
  File "C:\Users\User\OneDrive\Desktop\Digital Land\Digital-Land-Server\venv\Lib\site-packages\starlette\middleware\cors.py", line 144, in simple_response
    await self.app(scope, receive, send)
  File "C:\Users\User\OneDrive\Desktop\Digital Land\Digital-Land-Server\venv\Lib\site-packages\starlette\middleware\exceptions.py", line 62, in __call__
    await wrap_app_handling_exceptions(self.app, conn)(scope, receive, send)
  File "C:\Users\User\OneDrive\Desktop\Digital Land\Digital-Land-Server\venv\Lib\site-packages\starlette\_exception_handler.py", line 62, in wrapped_app
    raise exc
  File "C:\Users\User\OneDrive\Desktop\Digital Land\Digital-Land-Server\venv\Lib\site-packages\starlette\_exception_handler.py", line 51, in wrapped_app
    await app(scope, receive, sender)
  File "C:\Users\User\OneDrive\Desktop\Digital Land\Digital-Land-Server\venv\Lib\site-packages\starlette\routing.py", line 715, in __call__
    await self.middleware_stack(scope, receive, send)
  File "C:\Users\User\OneDrive\Desktop\Digital Land\Digital-Land-Server\venv\Lib\site-packages\starlette\routing.py", line 735, in app
    await route.handle(scope, receive, send)
  File "C:\Users\User\OneDrive\Desktop\Digital Land\Digital-Land-Server\venv\Lib\site-packages\starlette\routing.py", line 288, in handle
    await self.app(scope, receive, send)
  File "C:\Users\User\OneDrive\Desktop\Digital Land\Digital-Land-Server\venv\Lib\site-packages\starlette\routing.py", line 76, in app
    await wrap_app_handling_exceptions(app, request)(scope, receive, send)
  File "C:\Users\User\OneDrive\Desktop\Digital Land\Digital-Land-Server\venv\Lib\site-packages\starlette\_exception_handler.py", line 62, in wrapped_app
    raise exc
  File "C:\Users\User\OneDrive\Desktop\Digital Land\Digital-Land-Server\venv\Lib\site-packages\starlette\_exception_handler.py", line 51, in wrapped_app
    await app(scope, receive, sender)
  File "C:\Users\User\OneDrive\Desktop\Digital Land\Digital-Land-Server\venv\Lib\site-packages\starlette\routing.py", line 73, in app
    response = await f(request)
               ^^^^^^^^^^^^^^^^
  File "C:\Users\User\OneDrive\Desktop\Digital Land\Digital-Land-Server\venv\Lib\site-packages\fastapi\routing.py", line 301, in app
    raw_response = await run_endpoint_function(
                   ^^^^^^^^^^^^^^^^^^^^^^^^^^^^
  File "C:\Users\User\OneDrive\Desktop\Digital Land\Digital-Land-Server\venv\Lib\site-packages\fastapi\routing.py", line 212, in run_endpoint_function
    return await dependant.call(**values)
           ^^^^^^^^^^^^^^^^^^^^^^^^^^^^^^
  File "C:\Users\User\OneDrive\Desktop\Digital Land\Digital-Land-Server\venv\Lib\site-packages\strawberry\fastapi\router.py", line 249, in handle_http_post
    return await self.run(
           ^^^^^^^^^^^^^^^
  File "C:\Users\User\OneDrive\Desktop\Digital Land\Digital-Land-Server\venv\Lib\site-packages\strawberry\http\async_base_view.py", line 200, in run
    result = await self.execute_operation(
             ^^^^^^^^^^^^^^^^^^^^^^^^^^^^^
  File "C:\Users\User\OneDrive\Desktop\Digital Land\Digital-Land-Server\venv\Lib\site-packages\strawberry\http\async_base_view.py", line 111, in execute_operation
    request_data = await self.parse_http_body(request_adapter)
                   ^^^^^^^^^^^^^^^^^^^^^^^^^^^^^^^^^^^^^^^^^^^
  File "C:\Users\User\OneDrive\Desktop\Digital Land\Digital-Land-Server\venv\Lib\site-packages\strawberry\http\async_base_view.py", line 335, in parse_http_body
    data = self.parse_json(await request.get_body())
                           ^^^^^^^^^^^^^^^^^^^^^^^^
  File "C:\Users\User\OneDrive\Desktop\Digital Land\Digital-Land-Server\venv\Lib\site-packages\strawberry\asgi\__init__.py", line 70, in get_body
    return await self.request.body()
           ^^^^^^^^^^^^^^^^^^^^^^^^^
  File "C:\Users\User\OneDrive\Desktop\Digital Land\Digital-Land-Server\venv\Lib\site-packages\starlette\requests.py", line 237, in body
    async for chunk in self.stream():
  File "C:\Users\User\OneDrive\Desktop\Digital Land\Digital-Land-Server\venv\Lib\site-packages\starlette\requests.py", line 231, in stream
    raise ClientDisconnect()
starlette.requests.ClientDisconnect
2024-12-03 13:15:00,474 - uvicorn.error - ERROR - Exception in ASGI application
Traceback (most recent call last):
  File "C:\Users\User\OneDrive\Desktop\Digital Land\Digital-Land-Server\venv\Lib\site-packages\uvicorn\protocols\http\httptools_impl.py", line 401, in run_asgi
    result = await app(  # type: ignore[func-returns-value]
             ^^^^^^^^^^^^^^^^^^^^^^^^^^^^^^^^^^^^^^^^^^^^^^
  File "C:\Users\User\OneDrive\Desktop\Digital Land\Digital-Land-Server\venv\Lib\site-packages\uvicorn\middleware\proxy_headers.py", line 60, in __call__
    return await self.app(scope, receive, send)
           ^^^^^^^^^^^^^^^^^^^^^^^^^^^^^^^^^^^^
  File "C:\Users\User\OneDrive\Desktop\Digital Land\Digital-Land-Server\venv\Lib\site-packages\fastapi\applications.py", line 1054, in __call__
    await super().__call__(scope, receive, send)
  File "C:\Users\User\OneDrive\Desktop\Digital Land\Digital-Land-Server\venv\Lib\site-packages\starlette\applications.py", line 113, in __call__
    await self.middleware_stack(scope, receive, send)
  File "C:\Users\User\OneDrive\Desktop\Digital Land\Digital-Land-Server\venv\Lib\site-packages\starlette\middleware\errors.py", line 187, in __call__
    raise exc
  File "C:\Users\User\OneDrive\Desktop\Digital Land\Digital-Land-Server\venv\Lib\site-packages\starlette\middleware\errors.py", line 165, in __call__
    await self.app(scope, receive, _send)
  File "C:\Users\User\OneDrive\Desktop\Digital Land\Digital-Land-Server\venv\Lib\site-packages\starlette\middleware\cors.py", line 93, in __call__
    await self.simple_response(scope, receive, send, request_headers=headers)
  File "C:\Users\User\OneDrive\Desktop\Digital Land\Digital-Land-Server\venv\Lib\site-packages\starlette\middleware\cors.py", line 144, in simple_response
    await self.app(scope, receive, send)
  File "C:\Users\User\OneDrive\Desktop\Digital Land\Digital-Land-Server\venv\Lib\site-packages\starlette\middleware\exceptions.py", line 62, in __call__
    await wrap_app_handling_exceptions(self.app, conn)(scope, receive, send)
  File "C:\Users\User\OneDrive\Desktop\Digital Land\Digital-Land-Server\venv\Lib\site-packages\starlette\_exception_handler.py", line 62, in wrapped_app
    raise exc
  File "C:\Users\User\OneDrive\Desktop\Digital Land\Digital-Land-Server\venv\Lib\site-packages\starlette\_exception_handler.py", line 51, in wrapped_app
    await app(scope, receive, sender)
  File "C:\Users\User\OneDrive\Desktop\Digital Land\Digital-Land-Server\venv\Lib\site-packages\starlette\routing.py", line 715, in __call__
    await self.middleware_stack(scope, receive, send)
  File "C:\Users\User\OneDrive\Desktop\Digital Land\Digital-Land-Server\venv\Lib\site-packages\starlette\routing.py", line 735, in app
    await route.handle(scope, receive, send)
  File "C:\Users\User\OneDrive\Desktop\Digital Land\Digital-Land-Server\venv\Lib\site-packages\starlette\routing.py", line 288, in handle
    await self.app(scope, receive, send)
  File "C:\Users\User\OneDrive\Desktop\Digital Land\Digital-Land-Server\venv\Lib\site-packages\starlette\routing.py", line 76, in app
    await wrap_app_handling_exceptions(app, request)(scope, receive, send)
  File "C:\Users\User\OneDrive\Desktop\Digital Land\Digital-Land-Server\venv\Lib\site-packages\starlette\_exception_handler.py", line 62, in wrapped_app
    raise exc
  File "C:\Users\User\OneDrive\Desktop\Digital Land\Digital-Land-Server\venv\Lib\site-packages\starlette\_exception_handler.py", line 51, in wrapped_app
    await app(scope, receive, sender)
  File "C:\Users\User\OneDrive\Desktop\Digital Land\Digital-Land-Server\venv\Lib\site-packages\starlette\routing.py", line 73, in app
    response = await f(request)
               ^^^^^^^^^^^^^^^^
  File "C:\Users\User\OneDrive\Desktop\Digital Land\Digital-Land-Server\venv\Lib\site-packages\fastapi\routing.py", line 301, in app
    raw_response = await run_endpoint_function(
                   ^^^^^^^^^^^^^^^^^^^^^^^^^^^^
  File "C:\Users\User\OneDrive\Desktop\Digital Land\Digital-Land-Server\venv\Lib\site-packages\fastapi\routing.py", line 212, in run_endpoint_function
    return await dependant.call(**values)
           ^^^^^^^^^^^^^^^^^^^^^^^^^^^^^^
  File "C:\Users\User\OneDrive\Desktop\Digital Land\Digital-Land-Server\venv\Lib\site-packages\strawberry\fastapi\router.py", line 249, in handle_http_post
    return await self.run(
           ^^^^^^^^^^^^^^^
  File "C:\Users\User\OneDrive\Desktop\Digital Land\Digital-Land-Server\venv\Lib\site-packages\strawberry\http\async_base_view.py", line 200, in run
    result = await self.execute_operation(
             ^^^^^^^^^^^^^^^^^^^^^^^^^^^^^
  File "C:\Users\User\OneDrive\Desktop\Digital Land\Digital-Land-Server\venv\Lib\site-packages\strawberry\http\async_base_view.py", line 111, in execute_operation
    request_data = await self.parse_http_body(request_adapter)
                   ^^^^^^^^^^^^^^^^^^^^^^^^^^^^^^^^^^^^^^^^^^^
  File "C:\Users\User\OneDrive\Desktop\Digital Land\Digital-Land-Server\venv\Lib\site-packages\strawberry\http\async_base_view.py", line 335, in parse_http_body
    data = self.parse_json(await request.get_body())
                           ^^^^^^^^^^^^^^^^^^^^^^^^
  File "C:\Users\User\OneDrive\Desktop\Digital Land\Digital-Land-Server\venv\Lib\site-packages\strawberry\asgi\__init__.py", line 70, in get_body
    return await self.request.body()
           ^^^^^^^^^^^^^^^^^^^^^^^^^
  File "C:\Users\User\OneDrive\Desktop\Digital Land\Digital-Land-Server\venv\Lib\site-packages\starlette\requests.py", line 237, in body
    async for chunk in self.stream():
  File "C:\Users\User\OneDrive\Desktop\Digital Land\Digital-Land-Server\venv\Lib\site-packages\starlette\requests.py", line 231, in stream
    raise ClientDisconnect()
starlette.requests.ClientDisconnect
2024-12-03 20:28:55,684 - uvicorn.error - ERROR - Exception in ASGI application
Traceback (most recent call last):
  File "C:\Users\User\OneDrive\Desktop\Digital Land\Digital-Land-Server\venv\Lib\site-packages\uvicorn\protocols\http\httptools_impl.py", line 401, in run_asgi
    result = await app(  # type: ignore[func-returns-value]
             ^^^^^^^^^^^^^^^^^^^^^^^^^^^^^^^^^^^^^^^^^^^^^^
  File "C:\Users\User\OneDrive\Desktop\Digital Land\Digital-Land-Server\venv\Lib\site-packages\uvicorn\middleware\proxy_headers.py", line 60, in __call__
    return await self.app(scope, receive, send)
           ^^^^^^^^^^^^^^^^^^^^^^^^^^^^^^^^^^^^
  File "C:\Users\User\OneDrive\Desktop\Digital Land\Digital-Land-Server\venv\Lib\site-packages\fastapi\applications.py", line 1054, in __call__
    await super().__call__(scope, receive, send)
  File "C:\Users\User\OneDrive\Desktop\Digital Land\Digital-Land-Server\venv\Lib\site-packages\starlette\applications.py", line 113, in __call__
    await self.middleware_stack(scope, receive, send)
  File "C:\Users\User\OneDrive\Desktop\Digital Land\Digital-Land-Server\venv\Lib\site-packages\starlette\middleware\errors.py", line 187, in __call__
    raise exc
  File "C:\Users\User\OneDrive\Desktop\Digital Land\Digital-Land-Server\venv\Lib\site-packages\starlette\middleware\errors.py", line 165, in __call__
    await self.app(scope, receive, _send)
  File "C:\Users\User\OneDrive\Desktop\Digital Land\Digital-Land-Server\venv\Lib\site-packages\starlette\middleware\cors.py", line 93, in __call__
    await self.simple_response(scope, receive, send, request_headers=headers)
  File "C:\Users\User\OneDrive\Desktop\Digital Land\Digital-Land-Server\venv\Lib\site-packages\starlette\middleware\cors.py", line 144, in simple_response
    await self.app(scope, receive, send)
  File "C:\Users\User\OneDrive\Desktop\Digital Land\Digital-Land-Server\venv\Lib\site-packages\starlette\middleware\exceptions.py", line 62, in __call__
    await wrap_app_handling_exceptions(self.app, conn)(scope, receive, send)
  File "C:\Users\User\OneDrive\Desktop\Digital Land\Digital-Land-Server\venv\Lib\site-packages\starlette\_exception_handler.py", line 62, in wrapped_app
    raise exc
  File "C:\Users\User\OneDrive\Desktop\Digital Land\Digital-Land-Server\venv\Lib\site-packages\starlette\_exception_handler.py", line 51, in wrapped_app
    await app(scope, receive, sender)
  File "C:\Users\User\OneDrive\Desktop\Digital Land\Digital-Land-Server\venv\Lib\site-packages\starlette\routing.py", line 715, in __call__
    await self.middleware_stack(scope, receive, send)
  File "C:\Users\User\OneDrive\Desktop\Digital Land\Digital-Land-Server\venv\Lib\site-packages\starlette\routing.py", line 735, in app
    await route.handle(scope, receive, send)
  File "C:\Users\User\OneDrive\Desktop\Digital Land\Digital-Land-Server\venv\Lib\site-packages\starlette\routing.py", line 288, in handle
    await self.app(scope, receive, send)
  File "C:\Users\User\OneDrive\Desktop\Digital Land\Digital-Land-Server\venv\Lib\site-packages\starlette\routing.py", line 76, in app
    await wrap_app_handling_exceptions(app, request)(scope, receive, send)
  File "C:\Users\User\OneDrive\Desktop\Digital Land\Digital-Land-Server\venv\Lib\site-packages\starlette\_exception_handler.py", line 62, in wrapped_app
    raise exc
  File "C:\Users\User\OneDrive\Desktop\Digital Land\Digital-Land-Server\venv\Lib\site-packages\starlette\_exception_handler.py", line 51, in wrapped_app
    await app(scope, receive, sender)
  File "C:\Users\User\OneDrive\Desktop\Digital Land\Digital-Land-Server\venv\Lib\site-packages\starlette\routing.py", line 73, in app
    response = await f(request)
               ^^^^^^^^^^^^^^^^
  File "C:\Users\User\OneDrive\Desktop\Digital Land\Digital-Land-Server\venv\Lib\site-packages\fastapi\routing.py", line 301, in app
    raw_response = await run_endpoint_function(
                   ^^^^^^^^^^^^^^^^^^^^^^^^^^^^
  File "C:\Users\User\OneDrive\Desktop\Digital Land\Digital-Land-Server\venv\Lib\site-packages\fastapi\routing.py", line 212, in run_endpoint_function
    return await dependant.call(**values)
           ^^^^^^^^^^^^^^^^^^^^^^^^^^^^^^
  File "C:\Users\User\OneDrive\Desktop\Digital Land\Digital-Land-Server\venv\Lib\site-packages\strawberry\fastapi\router.py", line 249, in handle_http_post
    return await self.run(
           ^^^^^^^^^^^^^^^
  File "C:\Users\User\OneDrive\Desktop\Digital Land\Digital-Land-Server\venv\Lib\site-packages\strawberry\http\async_base_view.py", line 200, in run
    result = await self.execute_operation(
             ^^^^^^^^^^^^^^^^^^^^^^^^^^^^^
  File "C:\Users\User\OneDrive\Desktop\Digital Land\Digital-Land-Server\venv\Lib\site-packages\strawberry\http\async_base_view.py", line 111, in execute_operation
    request_data = await self.parse_http_body(request_adapter)
                   ^^^^^^^^^^^^^^^^^^^^^^^^^^^^^^^^^^^^^^^^^^^
  File "C:\Users\User\OneDrive\Desktop\Digital Land\Digital-Land-Server\venv\Lib\site-packages\strawberry\http\async_base_view.py", line 335, in parse_http_body
    data = self.parse_json(await request.get_body())
                           ^^^^^^^^^^^^^^^^^^^^^^^^
  File "C:\Users\User\OneDrive\Desktop\Digital Land\Digital-Land-Server\venv\Lib\site-packages\strawberry\asgi\__init__.py", line 70, in get_body
    return await self.request.body()
           ^^^^^^^^^^^^^^^^^^^^^^^^^
  File "C:\Users\User\OneDrive\Desktop\Digital Land\Digital-Land-Server\venv\Lib\site-packages\starlette\requests.py", line 237, in body
    async for chunk in self.stream():
  File "C:\Users\User\OneDrive\Desktop\Digital Land\Digital-Land-Server\venv\Lib\site-packages\starlette\requests.py", line 231, in stream
    raise ClientDisconnect()
starlette.requests.ClientDisconnect
2024-12-03 20:28:56,776 - uvicorn.error - ERROR - Exception in ASGI application
Traceback (most recent call last):
  File "C:\Users\User\OneDrive\Desktop\Digital Land\Digital-Land-Server\venv\Lib\site-packages\uvicorn\protocols\http\httptools_impl.py", line 401, in run_asgi
    result = await app(  # type: ignore[func-returns-value]
             ^^^^^^^^^^^^^^^^^^^^^^^^^^^^^^^^^^^^^^^^^^^^^^
  File "C:\Users\User\OneDrive\Desktop\Digital Land\Digital-Land-Server\venv\Lib\site-packages\uvicorn\middleware\proxy_headers.py", line 60, in __call__
    return await self.app(scope, receive, send)
           ^^^^^^^^^^^^^^^^^^^^^^^^^^^^^^^^^^^^
  File "C:\Users\User\OneDrive\Desktop\Digital Land\Digital-Land-Server\venv\Lib\site-packages\fastapi\applications.py", line 1054, in __call__
    await super().__call__(scope, receive, send)
  File "C:\Users\User\OneDrive\Desktop\Digital Land\Digital-Land-Server\venv\Lib\site-packages\starlette\applications.py", line 113, in __call__
    await self.middleware_stack(scope, receive, send)
  File "C:\Users\User\OneDrive\Desktop\Digital Land\Digital-Land-Server\venv\Lib\site-packages\starlette\middleware\errors.py", line 187, in __call__
    raise exc
  File "C:\Users\User\OneDrive\Desktop\Digital Land\Digital-Land-Server\venv\Lib\site-packages\starlette\middleware\errors.py", line 165, in __call__
    await self.app(scope, receive, _send)
  File "C:\Users\User\OneDrive\Desktop\Digital Land\Digital-Land-Server\venv\Lib\site-packages\starlette\middleware\cors.py", line 93, in __call__
    await self.simple_response(scope, receive, send, request_headers=headers)
  File "C:\Users\User\OneDrive\Desktop\Digital Land\Digital-Land-Server\venv\Lib\site-packages\starlette\middleware\cors.py", line 144, in simple_response
    await self.app(scope, receive, send)
  File "C:\Users\User\OneDrive\Desktop\Digital Land\Digital-Land-Server\venv\Lib\site-packages\starlette\middleware\exceptions.py", line 62, in __call__
    await wrap_app_handling_exceptions(self.app, conn)(scope, receive, send)
  File "C:\Users\User\OneDrive\Desktop\Digital Land\Digital-Land-Server\venv\Lib\site-packages\starlette\_exception_handler.py", line 62, in wrapped_app
    raise exc
  File "C:\Users\User\OneDrive\Desktop\Digital Land\Digital-Land-Server\venv\Lib\site-packages\starlette\_exception_handler.py", line 51, in wrapped_app
    await app(scope, receive, sender)
  File "C:\Users\User\OneDrive\Desktop\Digital Land\Digital-Land-Server\venv\Lib\site-packages\starlette\routing.py", line 715, in __call__
    await self.middleware_stack(scope, receive, send)
  File "C:\Users\User\OneDrive\Desktop\Digital Land\Digital-Land-Server\venv\Lib\site-packages\starlette\routing.py", line 735, in app
    await route.handle(scope, receive, send)
  File "C:\Users\User\OneDrive\Desktop\Digital Land\Digital-Land-Server\venv\Lib\site-packages\starlette\routing.py", line 288, in handle
    await self.app(scope, receive, send)
  File "C:\Users\User\OneDrive\Desktop\Digital Land\Digital-Land-Server\venv\Lib\site-packages\starlette\routing.py", line 76, in app
    await wrap_app_handling_exceptions(app, request)(scope, receive, send)
  File "C:\Users\User\OneDrive\Desktop\Digital Land\Digital-Land-Server\venv\Lib\site-packages\starlette\_exception_handler.py", line 62, in wrapped_app
    raise exc
  File "C:\Users\User\OneDrive\Desktop\Digital Land\Digital-Land-Server\venv\Lib\site-packages\starlette\_exception_handler.py", line 51, in wrapped_app
    await app(scope, receive, sender)
  File "C:\Users\User\OneDrive\Desktop\Digital Land\Digital-Land-Server\venv\Lib\site-packages\starlette\routing.py", line 73, in app
    response = await f(request)
               ^^^^^^^^^^^^^^^^
  File "C:\Users\User\OneDrive\Desktop\Digital Land\Digital-Land-Server\venv\Lib\site-packages\fastapi\routing.py", line 301, in app
    raw_response = await run_endpoint_function(
                   ^^^^^^^^^^^^^^^^^^^^^^^^^^^^
  File "C:\Users\User\OneDrive\Desktop\Digital Land\Digital-Land-Server\venv\Lib\site-packages\fastapi\routing.py", line 212, in run_endpoint_function
    return await dependant.call(**values)
           ^^^^^^^^^^^^^^^^^^^^^^^^^^^^^^
  File "C:\Users\User\OneDrive\Desktop\Digital Land\Digital-Land-Server\venv\Lib\site-packages\strawberry\fastapi\router.py", line 249, in handle_http_post
    return await self.run(
           ^^^^^^^^^^^^^^^
  File "C:\Users\User\OneDrive\Desktop\Digital Land\Digital-Land-Server\venv\Lib\site-packages\strawberry\http\async_base_view.py", line 200, in run
    result = await self.execute_operation(
             ^^^^^^^^^^^^^^^^^^^^^^^^^^^^^
  File "C:\Users\User\OneDrive\Desktop\Digital Land\Digital-Land-Server\venv\Lib\site-packages\strawberry\http\async_base_view.py", line 111, in execute_operation
    request_data = await self.parse_http_body(request_adapter)
                   ^^^^^^^^^^^^^^^^^^^^^^^^^^^^^^^^^^^^^^^^^^^
  File "C:\Users\User\OneDrive\Desktop\Digital Land\Digital-Land-Server\venv\Lib\site-packages\strawberry\http\async_base_view.py", line 335, in parse_http_body
    data = self.parse_json(await request.get_body())
                           ^^^^^^^^^^^^^^^^^^^^^^^^
  File "C:\Users\User\OneDrive\Desktop\Digital Land\Digital-Land-Server\venv\Lib\site-packages\strawberry\asgi\__init__.py", line 70, in get_body
    return await self.request.body()
           ^^^^^^^^^^^^^^^^^^^^^^^^^
  File "C:\Users\User\OneDrive\Desktop\Digital Land\Digital-Land-Server\venv\Lib\site-packages\starlette\requests.py", line 237, in body
    async for chunk in self.stream():
  File "C:\Users\User\OneDrive\Desktop\Digital Land\Digital-Land-Server\venv\Lib\site-packages\starlette\requests.py", line 231, in stream
    raise ClientDisconnect()
starlette.requests.ClientDisconnect
2024-12-03 20:44:06,696 - uvicorn.error - ERROR - Traceback (most recent call last):
  File "C:\Python312\Lib\asyncio\runners.py", line 118, in run
    return self._loop.run_until_complete(task)
           ^^^^^^^^^^^^^^^^^^^^^^^^^^^^^^^^^^^
  File "C:\Python312\Lib\asyncio\base_events.py", line 687, in run_until_complete
    return future.result()
           ^^^^^^^^^^^^^^^
asyncio.exceptions.CancelledError

During handling of the above exception, another exception occurred:

Traceback (most recent call last):
  File "C:\Python312\Lib\asyncio\runners.py", line 194, in run
    return runner.run(main)
           ^^^^^^^^^^^^^^^^
  File "C:\Python312\Lib\asyncio\runners.py", line 123, in run
    raise KeyboardInterrupt()
KeyboardInterrupt

During handling of the above exception, another exception occurred:

Traceback (most recent call last):
  File "C:\Users\User\OneDrive\Desktop\Digital Land\Digital-Land-Server\venv\Lib\site-packages\starlette\routing.py", line 700, in lifespan
    await receive()
  File "C:\Users\User\OneDrive\Desktop\Digital Land\Digital-Land-Server\venv\Lib\site-packages\uvicorn\lifespan\on.py", line 137, in receive
    return await self.receive_queue.get()
           ^^^^^^^^^^^^^^^^^^^^^^^^^^^^^^
  File "C:\Python312\Lib\asyncio\queues.py", line 158, in get
    await getter
asyncio.exceptions.CancelledError

2024-12-03 20:58:04,022 - uvicorn.error - ERROR - Traceback (most recent call last):
  File "C:\Python312\Lib\asyncio\runners.py", line 118, in run
    return self._loop.run_until_complete(task)
           ^^^^^^^^^^^^^^^^^^^^^^^^^^^^^^^^^^^
  File "C:\Python312\Lib\asyncio\base_events.py", line 687, in run_until_complete
    return future.result()
           ^^^^^^^^^^^^^^^
asyncio.exceptions.CancelledError

During handling of the above exception, another exception occurred:

Traceback (most recent call last):
  File "C:\Python312\Lib\asyncio\runners.py", line 194, in run
    return runner.run(main)
           ^^^^^^^^^^^^^^^^
  File "C:\Python312\Lib\asyncio\runners.py", line 123, in run
    raise KeyboardInterrupt()
KeyboardInterrupt

During handling of the above exception, another exception occurred:

Traceback (most recent call last):
  File "C:\Users\User\OneDrive\Desktop\Digital Land\Digital-Land-Server\venv\Lib\site-packages\starlette\routing.py", line 700, in lifespan
    await receive()
  File "C:\Users\User\OneDrive\Desktop\Digital Land\Digital-Land-Server\venv\Lib\site-packages\uvicorn\lifespan\on.py", line 137, in receive
    return await self.receive_queue.get()
           ^^^^^^^^^^^^^^^^^^^^^^^^^^^^^^
  File "C:\Python312\Lib\asyncio\queues.py", line 158, in get
    await getter
asyncio.exceptions.CancelledError

2024-12-03 20:58:26,573 - uvicorn.error - ERROR - Traceback (most recent call last):
  File "C:\Python312\Lib\asyncio\runners.py", line 118, in run
    return self._loop.run_until_complete(task)
           ^^^^^^^^^^^^^^^^^^^^^^^^^^^^^^^^^^^
  File "C:\Python312\Lib\asyncio\base_events.py", line 687, in run_until_complete
    return future.result()
           ^^^^^^^^^^^^^^^
asyncio.exceptions.CancelledError

During handling of the above exception, another exception occurred:

Traceback (most recent call last):
  File "C:\Python312\Lib\asyncio\runners.py", line 194, in run
    return runner.run(main)
           ^^^^^^^^^^^^^^^^
  File "C:\Python312\Lib\asyncio\runners.py", line 123, in run
    raise KeyboardInterrupt()
KeyboardInterrupt

During handling of the above exception, another exception occurred:

Traceback (most recent call last):
  File "C:\Users\User\OneDrive\Desktop\Digital Land\Digital-Land-Server\venv\Lib\site-packages\starlette\routing.py", line 700, in lifespan
    await receive()
  File "C:\Users\User\OneDrive\Desktop\Digital Land\Digital-Land-Server\venv\Lib\site-packages\uvicorn\lifespan\on.py", line 137, in receive
    return await self.receive_queue.get()
           ^^^^^^^^^^^^^^^^^^^^^^^^^^^^^^
  File "C:\Python312\Lib\asyncio\queues.py", line 158, in get
    await getter
asyncio.exceptions.CancelledError

2024-12-03 20:58:43,796 - uvicorn.error - ERROR - Traceback (most recent call last):
  File "C:\Python312\Lib\asyncio\runners.py", line 118, in run
    return self._loop.run_until_complete(task)
           ^^^^^^^^^^^^^^^^^^^^^^^^^^^^^^^^^^^
  File "C:\Python312\Lib\asyncio\base_events.py", line 687, in run_until_complete
    return future.result()
           ^^^^^^^^^^^^^^^
asyncio.exceptions.CancelledError

During handling of the above exception, another exception occurred:

Traceback (most recent call last):
  File "C:\Python312\Lib\asyncio\runners.py", line 194, in run
    return runner.run(main)
           ^^^^^^^^^^^^^^^^
  File "C:\Python312\Lib\asyncio\runners.py", line 123, in run
    raise KeyboardInterrupt()
KeyboardInterrupt

During handling of the above exception, another exception occurred:

Traceback (most recent call last):
  File "C:\Users\User\OneDrive\Desktop\Digital Land\Digital-Land-Server\venv\Lib\site-packages\starlette\routing.py", line 700, in lifespan
    await receive()
  File "C:\Users\User\OneDrive\Desktop\Digital Land\Digital-Land-Server\venv\Lib\site-packages\uvicorn\lifespan\on.py", line 137, in receive
    return await self.receive_queue.get()
           ^^^^^^^^^^^^^^^^^^^^^^^^^^^^^^
  File "C:\Python312\Lib\asyncio\queues.py", line 158, in get
    await getter
asyncio.exceptions.CancelledError

2024-12-03 21:14:29,625 - uvicorn.error - ERROR - Traceback (most recent call last):
  File "C:\Python312\Lib\asyncio\runners.py", line 118, in run
    return self._loop.run_until_complete(task)
           ^^^^^^^^^^^^^^^^^^^^^^^^^^^^^^^^^^^
  File "C:\Python312\Lib\asyncio\base_events.py", line 687, in run_until_complete
    return future.result()
           ^^^^^^^^^^^^^^^
asyncio.exceptions.CancelledError

During handling of the above exception, another exception occurred:

Traceback (most recent call last):
  File "C:\Python312\Lib\asyncio\runners.py", line 194, in run
    return runner.run(main)
           ^^^^^^^^^^^^^^^^
  File "C:\Python312\Lib\asyncio\runners.py", line 123, in run
    raise KeyboardInterrupt()
KeyboardInterrupt

During handling of the above exception, another exception occurred:

Traceback (most recent call last):
  File "C:\Users\User\OneDrive\Desktop\Digital Land\Digital-Land-Server\venv\Lib\site-packages\starlette\routing.py", line 700, in lifespan
    await receive()
  File "C:\Users\User\OneDrive\Desktop\Digital Land\Digital-Land-Server\venv\Lib\site-packages\uvicorn\lifespan\on.py", line 137, in receive
    return await self.receive_queue.get()
           ^^^^^^^^^^^^^^^^^^^^^^^^^^^^^^
  File "C:\Python312\Lib\asyncio\queues.py", line 158, in get
    await getter
asyncio.exceptions.CancelledError

2024-12-06 01:21:40,200 - uvicorn.error - ERROR - Exception in ASGI application
Traceback (most recent call last):
  File "C:\Users\henok\Documents\DigitalLandRwanda\update payment\Digital-Land-Server\venv\Lib\site-packages\uvicorn\protocols\http\httptools_impl.py", line 401, in run_asgi
    result = await app(  # type: ignore[func-returns-value]
             ^^^^^^^^^^^^^^^^^^^^^^^^^^^^^^^^^^^^^^^^^^^^^^
  File "C:\Users\henok\Documents\DigitalLandRwanda\update payment\Digital-Land-Server\venv\Lib\site-packages\uvicorn\middleware\proxy_headers.py", line 60, in __call__
    return await self.app(scope, receive, send)
           ^^^^^^^^^^^^^^^^^^^^^^^^^^^^^^^^^^^^
  File "C:\Users\henok\Documents\DigitalLandRwanda\update payment\Digital-Land-Server\venv\Lib\site-packages\fastapi\applications.py", line 1054, in __call__
    await super().__call__(scope, receive, send)
  File "C:\Users\henok\Documents\DigitalLandRwanda\update payment\Digital-Land-Server\venv\Lib\site-packages\starlette\applications.py", line 113, in __call__
    await self.middleware_stack(scope, receive, send)
  File "C:\Users\henok\Documents\DigitalLandRwanda\update payment\Digital-Land-Server\venv\Lib\site-packages\starlette\middleware\errors.py", line 187, in __call__
    raise exc
  File "C:\Users\henok\Documents\DigitalLandRwanda\update payment\Digital-Land-Server\venv\Lib\site-packages\starlette\middleware\errors.py", line 165, in __call__
    await self.app(scope, receive, _send)
  File "C:\Users\henok\Documents\DigitalLandRwanda\update payment\Digital-Land-Server\venv\Lib\site-packages\starlette\middleware\cors.py", line 93, in __call__
    await self.simple_response(scope, receive, send, request_headers=headers)
  File "C:\Users\henok\Documents\DigitalLandRwanda\update payment\Digital-Land-Server\venv\Lib\site-packages\starlette\middleware\cors.py", line 144, in simple_response
    await self.app(scope, receive, send)
  File "C:\Users\henok\Documents\DigitalLandRwanda\update payment\Digital-Land-Server\venv\Lib\site-packages\starlette\middleware\exceptions.py", line 62, in __call__
    await wrap_app_handling_exceptions(self.app, conn)(scope, receive, send)
  File "C:\Users\henok\Documents\DigitalLandRwanda\update payment\Digital-Land-Server\venv\Lib\site-packages\starlette\_exception_handler.py", line 62, in wrapped_app
    raise exc
  File "C:\Users\henok\Documents\DigitalLandRwanda\update payment\Digital-Land-Server\venv\Lib\site-packages\starlette\_exception_handler.py", line 51, in wrapped_app
    await app(scope, receive, sender)
  File "C:\Users\henok\Documents\DigitalLandRwanda\update payment\Digital-Land-Server\venv\Lib\site-packages\starlette\routing.py", line 715, in __call__
    await self.middleware_stack(scope, receive, send)
  File "C:\Users\henok\Documents\DigitalLandRwanda\update payment\Digital-Land-Server\venv\Lib\site-packages\starlette\routing.py", line 735, in app
    await route.handle(scope, receive, send)
  File "C:\Users\henok\Documents\DigitalLandRwanda\update payment\Digital-Land-Server\venv\Lib\site-packages\starlette\routing.py", line 288, in handle
    await self.app(scope, receive, send)
  File "C:\Users\henok\Documents\DigitalLandRwanda\update payment\Digital-Land-Server\venv\Lib\site-packages\starlette\routing.py", line 76, in app
    await wrap_app_handling_exceptions(app, request)(scope, receive, send)
  File "C:\Users\henok\Documents\DigitalLandRwanda\update payment\Digital-Land-Server\venv\Lib\site-packages\starlette\_exception_handler.py", line 62, in wrapped_app
    raise exc
  File "C:\Users\henok\Documents\DigitalLandRwanda\update payment\Digital-Land-Server\venv\Lib\site-packages\starlette\_exception_handler.py", line 51, in wrapped_app
    await app(scope, receive, sender)
  File "C:\Users\henok\Documents\DigitalLandRwanda\update payment\Digital-Land-Server\venv\Lib\site-packages\starlette\routing.py", line 73, in app
    response = await f(request)
               ^^^^^^^^^^^^^^^^
  File "C:\Users\henok\Documents\DigitalLandRwanda\update payment\Digital-Land-Server\venv\Lib\site-packages\fastapi\routing.py", line 301, in app
    raw_response = await run_endpoint_function(
                   ^^^^^^^^^^^^^^^^^^^^^^^^^^^^
  File "C:\Users\henok\Documents\DigitalLandRwanda\update payment\Digital-Land-Server\venv\Lib\site-packages\fastapi\routing.py", line 212, in run_endpoint_function
    return await dependant.call(**values)
           ^^^^^^^^^^^^^^^^^^^^^^^^^^^^^^
  File "C:\Users\henok\Documents\DigitalLandRwanda\update payment\Digital-Land-Server\venv\Lib\site-packages\strawberry\fastapi\router.py", line 249, in handle_http_post
    return await self.run(
           ^^^^^^^^^^^^^^^
  File "C:\Users\henok\Documents\DigitalLandRwanda\update payment\Digital-Land-Server\venv\Lib\site-packages\strawberry\http\async_base_view.py", line 200, in run
    result = await self.execute_operation(
             ^^^^^^^^^^^^^^^^^^^^^^^^^^^^^
  File "C:\Users\henok\Documents\DigitalLandRwanda\update payment\Digital-Land-Server\venv\Lib\site-packages\strawberry\http\async_base_view.py", line 111, in execute_operation
    request_data = await self.parse_http_body(request_adapter)
                   ^^^^^^^^^^^^^^^^^^^^^^^^^^^^^^^^^^^^^^^^^^^
  File "C:\Users\henok\Documents\DigitalLandRwanda\update payment\Digital-Land-Server\venv\Lib\site-packages\strawberry\http\async_base_view.py", line 335, in parse_http_body
    data = self.parse_json(await request.get_body())
                           ^^^^^^^^^^^^^^^^^^^^^^^^
  File "C:\Users\henok\Documents\DigitalLandRwanda\update payment\Digital-Land-Server\venv\Lib\site-packages\strawberry\asgi\__init__.py", line 70, in get_body
    return await self.request.body()
           ^^^^^^^^^^^^^^^^^^^^^^^^^
  File "C:\Users\henok\Documents\DigitalLandRwanda\update payment\Digital-Land-Server\venv\Lib\site-packages\starlette\requests.py", line 237, in body
    async for chunk in self.stream():
  File "C:\Users\henok\Documents\DigitalLandRwanda\update payment\Digital-Land-Server\venv\Lib\site-packages\starlette\requests.py", line 231, in stream
    raise ClientDisconnect()
starlette.requests.ClientDisconnect
2024-12-06 01:21:41,537 - uvicorn.error - ERROR - Exception in ASGI application
Traceback (most recent call last):
  File "C:\Users\henok\Documents\DigitalLandRwanda\update payment\Digital-Land-Server\venv\Lib\site-packages\uvicorn\protocols\http\httptools_impl.py", line 401, in run_asgi
    result = await app(  # type: ignore[func-returns-value]
             ^^^^^^^^^^^^^^^^^^^^^^^^^^^^^^^^^^^^^^^^^^^^^^
  File "C:\Users\henok\Documents\DigitalLandRwanda\update payment\Digital-Land-Server\venv\Lib\site-packages\uvicorn\middleware\proxy_headers.py", line 60, in __call__
    return await self.app(scope, receive, send)
           ^^^^^^^^^^^^^^^^^^^^^^^^^^^^^^^^^^^^
  File "C:\Users\henok\Documents\DigitalLandRwanda\update payment\Digital-Land-Server\venv\Lib\site-packages\fastapi\applications.py", line 1054, in __call__
    await super().__call__(scope, receive, send)
  File "C:\Users\henok\Documents\DigitalLandRwanda\update payment\Digital-Land-Server\venv\Lib\site-packages\starlette\applications.py", line 113, in __call__
    await self.middleware_stack(scope, receive, send)
  File "C:\Users\henok\Documents\DigitalLandRwanda\update payment\Digital-Land-Server\venv\Lib\site-packages\starlette\middleware\errors.py", line 187, in __call__
    raise exc
  File "C:\Users\henok\Documents\DigitalLandRwanda\update payment\Digital-Land-Server\venv\Lib\site-packages\starlette\middleware\errors.py", line 165, in __call__
    await self.app(scope, receive, _send)
  File "C:\Users\henok\Documents\DigitalLandRwanda\update payment\Digital-Land-Server\venv\Lib\site-packages\starlette\middleware\cors.py", line 93, in __call__
    await self.simple_response(scope, receive, send, request_headers=headers)
  File "C:\Users\henok\Documents\DigitalLandRwanda\update payment\Digital-Land-Server\venv\Lib\site-packages\starlette\middleware\cors.py", line 144, in simple_response
    await self.app(scope, receive, send)
  File "C:\Users\henok\Documents\DigitalLandRwanda\update payment\Digital-Land-Server\venv\Lib\site-packages\starlette\middleware\exceptions.py", line 62, in __call__
    await wrap_app_handling_exceptions(self.app, conn)(scope, receive, send)
  File "C:\Users\henok\Documents\DigitalLandRwanda\update payment\Digital-Land-Server\venv\Lib\site-packages\starlette\_exception_handler.py", line 62, in wrapped_app
    raise exc
  File "C:\Users\henok\Documents\DigitalLandRwanda\update payment\Digital-Land-Server\venv\Lib\site-packages\starlette\_exception_handler.py", line 51, in wrapped_app
    await app(scope, receive, sender)
  File "C:\Users\henok\Documents\DigitalLandRwanda\update payment\Digital-Land-Server\venv\Lib\site-packages\starlette\routing.py", line 715, in __call__
    await self.middleware_stack(scope, receive, send)
  File "C:\Users\henok\Documents\DigitalLandRwanda\update payment\Digital-Land-Server\venv\Lib\site-packages\starlette\routing.py", line 735, in app
    await route.handle(scope, receive, send)
  File "C:\Users\henok\Documents\DigitalLandRwanda\update payment\Digital-Land-Server\venv\Lib\site-packages\starlette\routing.py", line 288, in handle
    await self.app(scope, receive, send)
  File "C:\Users\henok\Documents\DigitalLandRwanda\update payment\Digital-Land-Server\venv\Lib\site-packages\starlette\routing.py", line 76, in app
    await wrap_app_handling_exceptions(app, request)(scope, receive, send)
  File "C:\Users\henok\Documents\DigitalLandRwanda\update payment\Digital-Land-Server\venv\Lib\site-packages\starlette\_exception_handler.py", line 62, in wrapped_app
    raise exc
  File "C:\Users\henok\Documents\DigitalLandRwanda\update payment\Digital-Land-Server\venv\Lib\site-packages\starlette\_exception_handler.py", line 51, in wrapped_app
    await app(scope, receive, sender)
  File "C:\Users\henok\Documents\DigitalLandRwanda\update payment\Digital-Land-Server\venv\Lib\site-packages\starlette\routing.py", line 73, in app
    response = await f(request)
               ^^^^^^^^^^^^^^^^
  File "C:\Users\henok\Documents\DigitalLandRwanda\update payment\Digital-Land-Server\venv\Lib\site-packages\fastapi\routing.py", line 301, in app
    raw_response = await run_endpoint_function(
                   ^^^^^^^^^^^^^^^^^^^^^^^^^^^^
  File "C:\Users\henok\Documents\DigitalLandRwanda\update payment\Digital-Land-Server\venv\Lib\site-packages\fastapi\routing.py", line 212, in run_endpoint_function
    return await dependant.call(**values)
           ^^^^^^^^^^^^^^^^^^^^^^^^^^^^^^
  File "C:\Users\henok\Documents\DigitalLandRwanda\update payment\Digital-Land-Server\venv\Lib\site-packages\strawberry\fastapi\router.py", line 249, in handle_http_post
    return await self.run(
           ^^^^^^^^^^^^^^^
  File "C:\Users\henok\Documents\DigitalLandRwanda\update payment\Digital-Land-Server\venv\Lib\site-packages\strawberry\http\async_base_view.py", line 200, in run
    result = await self.execute_operation(
             ^^^^^^^^^^^^^^^^^^^^^^^^^^^^^
  File "C:\Users\henok\Documents\DigitalLandRwanda\update payment\Digital-Land-Server\venv\Lib\site-packages\strawberry\http\async_base_view.py", line 111, in execute_operation
    request_data = await self.parse_http_body(request_adapter)
                   ^^^^^^^^^^^^^^^^^^^^^^^^^^^^^^^^^^^^^^^^^^^
  File "C:\Users\henok\Documents\DigitalLandRwanda\update payment\Digital-Land-Server\venv\Lib\site-packages\strawberry\http\async_base_view.py", line 335, in parse_http_body
    data = self.parse_json(await request.get_body())
                           ^^^^^^^^^^^^^^^^^^^^^^^^
  File "C:\Users\henok\Documents\DigitalLandRwanda\update payment\Digital-Land-Server\venv\Lib\site-packages\strawberry\asgi\__init__.py", line 70, in get_body
    return await self.request.body()
           ^^^^^^^^^^^^^^^^^^^^^^^^^
  File "C:\Users\henok\Documents\DigitalLandRwanda\update payment\Digital-Land-Server\venv\Lib\site-packages\starlette\requests.py", line 237, in body
    async for chunk in self.stream():
  File "C:\Users\henok\Documents\DigitalLandRwanda\update payment\Digital-Land-Server\venv\Lib\site-packages\starlette\requests.py", line 231, in stream
    raise ClientDisconnect()
starlette.requests.ClientDisconnect
2024-12-06 03:57:08,214 - uvicorn.error - ERROR - Traceback (most recent call last):
  File "C:\Users\henok\AppData\Local\Programs\Python\Python312\Lib\asyncio\runners.py", line 118, in run
    return self._loop.run_until_complete(task)
           ^^^^^^^^^^^^^^^^^^^^^^^^^^^^^^^^^^^
  File "C:\Users\henok\AppData\Local\Programs\Python\Python312\Lib\asyncio\base_events.py", line 687, in run_until_complete
    return future.result()
           ^^^^^^^^^^^^^^^
asyncio.exceptions.CancelledError

During handling of the above exception, another exception occurred:

Traceback (most recent call last):
  File "C:\Users\henok\AppData\Local\Programs\Python\Python312\Lib\asyncio\runners.py", line 194, in run
    return runner.run(main)
           ^^^^^^^^^^^^^^^^
  File "C:\Users\henok\AppData\Local\Programs\Python\Python312\Lib\asyncio\runners.py", line 123, in run
    raise KeyboardInterrupt()
KeyboardInterrupt

During handling of the above exception, another exception occurred:

Traceback (most recent call last):
  File "C:\Users\henok\Documents\DigitalLandRwanda\update payment\Digital-Land-Server\venv\Lib\site-packages\starlette\routing.py", line 700, in lifespan
    await receive()
  File "C:\Users\henok\Documents\DigitalLandRwanda\update payment\Digital-Land-Server\venv\Lib\site-packages\uvicorn\lifespan\on.py", line 137, in receive
    return await self.receive_queue.get()
           ^^^^^^^^^^^^^^^^^^^^^^^^^^^^^^
  File "C:\Users\henok\AppData\Local\Programs\Python\Python312\Lib\asyncio\queues.py", line 158, in get
    await getter
asyncio.exceptions.CancelledError

